[2023-11-13T04:13:20.086+0000] {taskinstance.py:1159} INFO - Dependencies all met for dep_context=non-requeueable deps ti=<TaskInstance: ETL_FinancialReport.Import_BCTC_TO_SQL manual__2023-11-13T04:12:13.649505+00:00 [queued]>
[2023-11-13T04:13:20.132+0000] {taskinstance.py:1159} INFO - Dependencies all met for dep_context=requeueable deps ti=<TaskInstance: ETL_FinancialReport.Import_BCTC_TO_SQL manual__2023-11-13T04:12:13.649505+00:00 [queued]>
[2023-11-13T04:13:20.133+0000] {taskinstance.py:1361} INFO - Starting attempt 1 of 2
[2023-11-13T04:13:20.231+0000] {taskinstance.py:1382} INFO - Executing <Task(PythonOperator): Import_BCTC_TO_SQL> on 2023-11-13 04:12:13.649505+00:00
[2023-11-13T04:13:20.240+0000] {standard_task_runner.py:57} INFO - Started process 515 to run task
[2023-11-13T04:13:20.245+0000] {standard_task_runner.py:84} INFO - Running: ['airflow', 'tasks', 'run', 'ETL_FinancialReport', 'Import_BCTC_TO_SQL', 'manual__2023-11-13T04:12:13.649505+00:00', '--job-id', '5', '--raw', '--subdir', 'DAGS_FOLDER/updateBCTC.py', '--cfg-path', '/tmp/tmp1q22b6o2']
[2023-11-13T04:13:20.247+0000] {standard_task_runner.py:85} INFO - Job 5: Subtask Import_BCTC_TO_SQL
[2023-11-13T04:13:20.482+0000] {task_command.py:416} INFO - Running <TaskInstance: ETL_FinancialReport.Import_BCTC_TO_SQL manual__2023-11-13T04:12:13.649505+00:00 [running]> on host 8de48f26182c
[2023-11-13T04:13:20.824+0000] {taskinstance.py:1662} INFO - Exporting env vars: AIRFLOW_CTX_DAG_EMAIL='trivominhit@gmail.com' AIRFLOW_CTX_DAG_OWNER='MinhTri' AIRFLOW_CTX_DAG_ID='ETL_FinancialReport' AIRFLOW_CTX_TASK_ID='Import_BCTC_TO_SQL' AIRFLOW_CTX_EXECUTION_DATE='2023-11-13T04:12:13.649505+00:00' AIRFLOW_CTX_TRY_NUMBER='1' AIRFLOW_CTX_DAG_RUN_ID='manual__2023-11-13T04:12:13.649505+00:00'
[2023-11-13T04:13:21.029+0000] {taskinstance.py:1937} ERROR - Task failed with exception
Traceback (most recent call last):
  File "/home/airflow/.local/lib/python3.8/site-packages/airflow/operators/python.py", line 192, in execute
    return_value = self.execute_callable()
  File "/home/airflow/.local/lib/python3.8/site-packages/airflow/operators/python.py", line 209, in execute_callable
    return self.python_callable(*self.op_args, **self.op_kwargs)
  File "/opt/airflow/dags/updateBCTC.py", line 32, in LoadBCTC
    cursor.execute('''
pyodbc.ProgrammingError: ('42000', '[42000] [Microsoft][ODBC Driver 17 for SQL Server][SQL Server]The incoming tabular data stream (TDS) remote procedure call (RPC) protocol stream is incorrect. Parameter 12 (""): The supplied value is not a valid instance of data type float. Check the source data for invalid values. An example of an invalid value is data of numeric type with scale greater than precision. (8023) (SQLExecDirectW)')
[2023-11-13T04:13:21.072+0000] {taskinstance.py:1400} INFO - Marking task as UP_FOR_RETRY. dag_id=ETL_FinancialReport, task_id=Import_BCTC_TO_SQL, execution_date=20231113T041213, start_date=20231113T041320, end_date=20231113T041321
[2023-11-13T04:13:21.117+0000] {logging_mixin.py:154} WARNING - /home/airflow/.local/lib/python3.8/site-packages/airflow/utils/email.py:154 RemovedInAirflow3Warning: Fetching SMTP credentials from configuration variables will be deprecated in a future release. Please set credentials using a connection instead.
[2023-11-13T04:13:21.118+0000] {configuration.py:1050} WARNING - section/key [smtp/smtp_user] not found in config
[2023-11-13T04:13:21.119+0000] {email.py:270} INFO - Email alerting: attempt 1
[2023-11-13T04:13:21.148+0000] {configuration.py:1050} WARNING - section/key [smtp/smtp_user] not found in config
[2023-11-13T04:13:21.149+0000] {email.py:270} INFO - Email alerting: attempt 1
[2023-11-13T04:13:21.151+0000] {taskinstance.py:2007} ERROR - Failed to send email to: ['trivominhit@gmail.com']
Traceback (most recent call last):
  File "/home/airflow/.local/lib/python3.8/site-packages/airflow/models/taskinstance.py", line 1518, in _run_raw_task
    self._execute_task_with_callbacks(context, test_mode, session=session)
  File "/home/airflow/.local/lib/python3.8/site-packages/airflow/models/taskinstance.py", line 1681, in _execute_task_with_callbacks
    result = self._execute_task(context, task_orig)
  File "/home/airflow/.local/lib/python3.8/site-packages/airflow/models/taskinstance.py", line 1744, in _execute_task
    result = execute_callable(context=context, **execute_callable_kwargs)
  File "/home/airflow/.local/lib/python3.8/site-packages/airflow/operators/python.py", line 192, in execute
    return_value = self.execute_callable()
  File "/home/airflow/.local/lib/python3.8/site-packages/airflow/operators/python.py", line 209, in execute_callable
    return self.python_callable(*self.op_args, **self.op_kwargs)
  File "/opt/airflow/dags/updateBCTC.py", line 32, in LoadBCTC
    cursor.execute('''
pyodbc.ProgrammingError: ('42000', '[42000] [Microsoft][ODBC Driver 17 for SQL Server][SQL Server]The incoming tabular data stream (TDS) remote procedure call (RPC) protocol stream is incorrect. Parameter 12 (""): The supplied value is not a valid instance of data type float. Check the source data for invalid values. An example of an invalid value is data of numeric type with scale greater than precision. (8023) (SQLExecDirectW)')

During handling of the above exception, another exception occurred:

Traceback (most recent call last):
  File "/home/airflow/.local/lib/python3.8/site-packages/airflow/models/taskinstance.py", line 2420, in email_alert
    send_email(task.email, subject, html_content)
  File "/home/airflow/.local/lib/python3.8/site-packages/airflow/utils/email.py", line 80, in send_email
    return backend(
  File "/home/airflow/.local/lib/python3.8/site-packages/airflow/utils/email.py", line 154, in send_email_smtp
    send_mime_email(e_from=mail_from, e_to=recipients, mime_msg=msg, conn_id=conn_id, dryrun=dryrun)
  File "/home/airflow/.local/lib/python3.8/site-packages/airflow/utils/email.py", line 272, in send_mime_email
    smtp_conn = _get_smtp_connection(smtp_host, smtp_port, smtp_timeout, smtp_ssl)
  File "/home/airflow/.local/lib/python3.8/site-packages/airflow/utils/email.py", line 316, in _get_smtp_connection
    return smtplib.SMTP(host=host, port=port, timeout=timeout)
  File "/usr/local/lib/python3.8/smtplib.py", line 255, in __init__
    (code, msg) = self.connect(host, port)
  File "/usr/local/lib/python3.8/smtplib.py", line 339, in connect
    self.sock = self._get_socket(host, port, self.timeout)
  File "/usr/local/lib/python3.8/smtplib.py", line 310, in _get_socket
    return socket.create_connection((host, port), timeout,
  File "/usr/local/lib/python3.8/socket.py", line 808, in create_connection
    raise err
  File "/usr/local/lib/python3.8/socket.py", line 796, in create_connection
    sock.connect(sa)
OSError: [Errno 99] Cannot assign requested address

During handling of the above exception, another exception occurred:

Traceback (most recent call last):
  File "/home/airflow/.local/lib/python3.8/site-packages/airflow/models/taskinstance.py", line 2005, in handle_failure
    self.email_alert(error, task)
  File "/home/airflow/.local/lib/python3.8/site-packages/airflow/models/taskinstance.py", line 2422, in email_alert
    send_email(task.email, subject, html_content_err)
  File "/home/airflow/.local/lib/python3.8/site-packages/airflow/utils/email.py", line 80, in send_email
    return backend(
  File "/home/airflow/.local/lib/python3.8/site-packages/airflow/utils/email.py", line 154, in send_email_smtp
    send_mime_email(e_from=mail_from, e_to=recipients, mime_msg=msg, conn_id=conn_id, dryrun=dryrun)
  File "/home/airflow/.local/lib/python3.8/site-packages/airflow/utils/email.py", line 272, in send_mime_email
    smtp_conn = _get_smtp_connection(smtp_host, smtp_port, smtp_timeout, smtp_ssl)
  File "/home/airflow/.local/lib/python3.8/site-packages/airflow/utils/email.py", line 316, in _get_smtp_connection
    return smtplib.SMTP(host=host, port=port, timeout=timeout)
  File "/usr/local/lib/python3.8/smtplib.py", line 255, in __init__
    (code, msg) = self.connect(host, port)
  File "/usr/local/lib/python3.8/smtplib.py", line 339, in connect
    self.sock = self._get_socket(host, port, self.timeout)
  File "/usr/local/lib/python3.8/smtplib.py", line 310, in _get_socket
    return socket.create_connection((host, port), timeout,
  File "/usr/local/lib/python3.8/socket.py", line 808, in create_connection
    raise err
  File "/usr/local/lib/python3.8/socket.py", line 796, in create_connection
    sock.connect(sa)
OSError: [Errno 99] Cannot assign requested address
[2023-11-13T04:13:21.270+0000] {standard_task_runner.py:104} ERROR - Failed to execute job 5 for task Import_BCTC_TO_SQL (('42000', '[42000] [Microsoft][ODBC Driver 17 for SQL Server][SQL Server]The incoming tabular data stream (TDS) remote procedure call (RPC) protocol stream is incorrect. Parameter 12 (""): The supplied value is not a valid instance of data type float. Check the source data for invalid values. An example of an invalid value is data of numeric type with scale greater than precision. (8023) (SQLExecDirectW)'); 515)
[2023-11-13T04:13:21.306+0000] {local_task_job_runner.py:228} INFO - Task exited with return code 1
[2023-11-13T04:13:21.354+0000] {taskinstance.py:2778} INFO - 0 downstream tasks scheduled from follow-on schedule check
